Workbook

Sheet Inventario APIs
A1: Inventario completo de APIs de gestión de Web Services – One Click Caribe
A2: Organizado por módulo. Ninguna API está implementada: el estado indica el nivel de especificación alcanzado. Los campos no definidos se marcan como "Pendiente".
A4: ID operación | B4: API | C4: Módulo | D4: Submódulo | E4: Propósito o descripción funcional | F4: Método HTTP | G4: Endpoint propuesto | H4: Datos de entrada principales | I4: Datos de salida principales | J4: Historias de usuario relacionadas | K4: Tipo de consumo | L4: Estado | M4: Observaciones
A5: API-01 · clientes.api · MOD-01 Gestión de Clientes y Solicitudes
A6: API-01-OP01 | B6: clientes.api | C6: MOD-01 Gestión de Clientes y Solicitudes | D6: SUB-01 | E6: Registrar cliente titular | F6: POST | G6: /api/v1/clientes | H6: documento, nombre, telefono, correo, nacionalidad, tipoCliente | I6: clienteId y datos registrados, fechaRegistro | J6: HU-001 | K6: Pública | L6: Especificada en historia de usuario (Corte 2)
A7: API-01-OP02 | B7: clientes.api | C7: MOD-01 Gestión de Clientes y Solicitudes | D7: SUB-01 | E7: Consultar cliente por documento (validación de duplicidad) | F7: GET | G7: /api/v1/clientes/{documento} | H7: documento | I7: Cliente encontrado o data = null | J7: HU-001 | K7: Pública | L7: Definida en Corte 1, pendiente de refinamiento | M7: FUN-02 es criterio de aceptación de HU-001.
A8: API-01-OP03 | B8: clientes.api | C8: MOD-01 Gestión de Clientes y Solicitudes | D8: SUB-01 | E8: Consultar historial de solicitudes del cliente | F8: GET | G8: /api/v1/clientes/{clienteId}/solicitudes | H8: clienteId | I8: Lista de solicitudes con su estado | J8: HU-002 | K8: Pública | L8: Definida en Corte 1, pendiente de refinamiento
A9: API-01-OP04 | B9: clientes.api | C9: MOD-01 Gestión de Clientes y Solicitudes | D9: SUB-01 | E9: Actualizar datos de contacto del cliente | F9: PUT | G9: /api/v1/clientes/{clienteId} | H9: clienteId, telefono, correo | I9: Cliente actualizado | J9: HU-003 | K9: Pública | L9: Definida en Corte 1, pendiente de refinamiento
A10: API-01-OP05 | B10: clientes.api | C10: MOD-01 Gestión de Clientes y Solicitudes | D10: SUB-01 | E10: Asociar pasajeros al cliente titular | F10: POST | G10: /api/v1/clientes/{clienteId}/pasajeros | H10: clienteId; pasajeros: nombre, documento, fechaNacimiento, nacionalidad, esTitular, numeroPasaporte, vencimientoPasaporte | I10: pasajeroId y edad de cada pasajero, totalPasajeros | J10: HU-004 | K10: Pública | L10: Especificada en historia de usuario (Corte 2) | M10: Agrega nacionalidad y pasaporte, que la entidad Pasajero del Corte 1 no tenía.
A11: API-01-OP06 | B11: clientes.api | C11: MOD-01 Gestión de Clientes y Solicitudes | D11: SUB-01 | E11: Consultar pasajeros del cliente (nacionalidad, edad y pasaporte) | F11: GET | G11: /api/v1/clientes/{clienteId}/pasajeros | H11: clienteId | I11: Pasajeros con nacionalidad, edad y pasaporte | J11: HU-016, HU-044 | K11: Interna (consumida por MOD-03 y MOD-07) | L11: Definida en Corte 1, pendiente de refinamiento
A12: API-01-OP07 | B12: clientes.api | C12: MOD-01 Gestión de Clientes y Solicitudes | D12: SUB-01 | E12: Consultar datos fiscales del cliente titular | F12: GET | G12: /api/v1/clientes/{clienteId}/datos-fiscales | H12: clienteId | I12: Nombre, documento y correo del titular | J12: HU-032 | K12: Interna (consumida por MOD-06) | L12: Definida en Corte 1, pendiente de refinamiento
A13: API-01-OP08 | B13: clientes.api | C13: MOD-01 Gestión de Clientes y Solicitudes | D13: SUB-02 | E13: Registrar itinerario base de la solicitud | F13: POST | G13: /api/v1/solicitudes | H13: clienteId, origen, destinos[], fechaSalida, fechaRegreso | I13: solicitudId, estado pendiente_alcance | J13: HU-005 | K13: Pública | L13: Especificada en historia de usuario (Corte 2) | M13: Reemplaza POST /clientes/{id}/solicitudes del Corte 1, que agrupaba FUN-06 a FUN-10.
A14: API-01-OP09 | B14: clientes.api | C14: MOD-01 Gestión de Clientes y Solicitudes | D14: SUB-02 | E14: Registrar alcance de la solicitud (composición, servicios, acomodación) | F14: PUT | G14: /api/v1/solicitudes/{solicitudId}/alcance | H14: solicitudId; composicion, servicios, tipoAcomodacion | I14: Alcance registrado, estado lista_para_cotizar | J14: HU-006 | K14: Pública | L14: Especificada en historia de usuario (Corte 2) | M14: Amplía el catálogo de servicios del Corte 1 con las líneas reales del negocio.
A15: API-01-OP10 | B15: clientes.api | C15: MOD-01 Gestión de Clientes y Solicitudes | D15: SUB-02 | E15: Consultar solicitud de viaje | F15: GET | G15: /api/v1/solicitudes/{solicitudId} | H15: solicitudId | I15: Itinerario, alcance y estado de la solicitud | J15: HU-013 | K15: Interna (consumida por MOD-03) | L15: Definida en Corte 1, pendiente de refinamiento
A16: API-02 · proveedores.api · MOD-02 Gestión de Proveedores
A17: API-02-OP01 | B17: proveedores.api | C17: MOD-02 Gestión de Proveedores | D17: SUB-03 | E17: Registrar proveedor con comisión pactada | F17: POST | G17: /api/v1/proveedores | H17: nombre, nit, tipoProveedor, servicios, comisionPorcentaje, correoContacto | I17: proveedorId, estado activo | J17: HU-007 | K17: Pública | L17: Especificada en historia de usuario (Corte 2)
A18: API-02-OP02 | B18: proveedores.api | C18: MOD-02 Gestión de Proveedores | D18: SUB-03 | E18: Consultar directorio de proveedores por tipo de servicio | F18: Pendiente | G18: Pendiente | H18: Pendiente | I18: Pendiente | J18: HU-008 | K18: Pública | L18: Pendiente (Corte 3)
A19: API-02-OP03 | B19: proveedores.api | C19: MOD-02 Gestión de Proveedores | D19: SUB-03 | E19: Actualizar condiciones comerciales de un proveedor | F19: Pendiente | G19: Pendiente | H19: Pendiente | I19: Pendiente | J19: HU-009 | K19: Pública | L19: Pendiente (Corte 3)
A20: API-02-OP04 | B20: proveedores.api | C20: MOD-02 Gestión de Proveedores | D20: SUB-03 | E20: Desactivar proveedor del directorio | F20: Pendiente | G20: Pendiente | H20: Pendiente | I20: Pendiente | J20: HU-010 | K20: Pública | L20: Pendiente (Corte 3)
A21: API-02-OP05 | B21: proveedores.api | C21: MOD-02 Gestión de Proveedores | D21: SUB-04 | E21: Consultar disponibilidad y tarifa vigente | F21: GET | G21: /api/v1/proveedores/disponibilidad | H21: proveedorId, tipoServicio, destino, fechaInicio, fechaFin, adultos, menores | I21: consultaId, disponible, tarifaNetaAdulto, tarifaNetaMenor, fechaHoraConsulta | J21: HU-011 | K21: Pública e interna (consumida por MOD-03) | L21: Especificada en historia de usuario (Corte 2)
A22: API-02-OP06 | B22: proveedores.api | C22: MOD-02 Gestión de Proveedores | D22: SUB-04 | E22: Comparar tarifas entre proveedores | F22: Pendiente | G22: Pendiente | H22: Pendiente | I22: Pendiente | J22: HU-012 | K22: Pública | L22: Pendiente (Corte 3)
A23: API-02-OP07 | B23: proveedores.api | C23: MOD-02 Gestión de Proveedores | D23: SUB-04 | E23: Solicitar reserva formal en la plataforma del proveedor | F23: POST | G23: /api/v1/proveedores/reservas | H23: Datos del servicio y de los pasajeros | I23: Respuesta del proveedor a la solicitud | J23: HU-037 | K23: Interna (consumida por MOD-07) | L23: Definida en Corte 1, pendiente de refinamiento
A24: API-02-OP08 | B24: proveedores.api | C24: MOD-02 Gestión de Proveedores | D24: SUB-03 | E24: Ejecutar pago neto en la plataforma del proveedor | F24: POST | G24: /api/v1/proveedores/{proveedorId}/pagos | H24: Monto neto, referencia, orden | I24: Resultado del pago en la plataforma | J24: HU-029 | K24: Interna (consumida por MOD-05) | L24: Definida en Corte 1, pendiente de refinamiento
A25: API-03 · cotizaciones.api · MOD-03 Gestión de Cotizaciones
A26: API-03-OP01 | B26: cotizaciones.api | C26: MOD-03 Gestión de Cotizaciones | D26: SUB-05 | E26: Crear cotización multiproveedor por segmento | F26: POST | G26: /api/v1/cotizaciones | H26: solicitudId; segmentos: orden, tipoServicio, destino, proveedorId, consultaId | I26: cotizacionId, segmentos, estado en_construccion | J26: HU-013 | K26: Pública | L26: Especificada en historia de usuario (Corte 2) | M26: En el Corte 1, POST /cotizaciones agrupaba FUN-21 a FUN-25; ahora se separa por historia.
A27: API-03-OP02 | B27: cotizaciones.api | C27: MOD-03 Gestión de Cotizaciones | D27: SUB-05 | E27: Calcular precio de venta con margen | F27: POST | G27: /api/v1/cotizaciones/{cotizacionId}/precios | H27: cotizacionId | I27: Precio por segmento y por pasajero, comisionTotal, precioVentaTotal | J27: HU-014 | K27: Pública | L27: Especificada en historia de usuario (Corte 2)
A28: API-03-OP03 | B28: cotizaciones.api | C28: MOD-03 Gestión de Cotizaciones | D28: SUB-05 | E28: Aplicar promoción vigente a la cotización | F28: Pendiente | G28: Pendiente | H28: Pendiente | I28: Pendiente | J28: HU-015 | K28: Pública | L28: Pendiente (Corte 3)
A29: API-03-OP04 | B29: cotizaciones.api | C29: MOD-03 Gestión de Cotizaciones | D29: SUB-05 | E29: Consolidar cotización final por pasajero | F29: POST | G29: /api/v1/cotizaciones/{cotizacionId}/consolidacion | H29: cotizacionId; pasajeroIds | I29: Valor por pasajero, totalCotizacion, estado consolidada | J29: HU-016 | K29: Pública | L29: Especificada en historia de usuario (Corte 2)
A30: API-03-OP05 | B30: cotizaciones.api | C30: MOD-03 Gestión de Cotizaciones | D30: SUB-06 | E30: Enviar cotización al cliente | F30: POST | G30: /api/v1/cotizaciones/{cotizacionId}/envio | H30: cotizacionId; canal | I30: fechaHoraEmision, vigenteHasta, estado enviada | J30: HU-017 | K30: Pública | L30: Especificada en historia de usuario (Corte 2)
A31: API-03-OP06 | B31: cotizaciones.api | C31: MOD-03 Gestión de Cotizaciones | D31: SUB-06 | E31: Registrar respuesta del cliente | F31: POST | G31: /api/v1/cotizaciones/{cotizacionId}/respuesta | H31: cotizacionId; respuesta, motivo | I31: Estado de la cotización, pagoRequeridoAntesDe | J31: HU-018 | K31: Pública | L31: Especificada en historia de usuario (Corte 2) | M31: Coincide con la ruta del Corte 1.
A32: API-03-OP07 | B32: cotizaciones.api | C32: MOD-03 Gestión de Cotizaciones | D32: SUB-06 | E32: Expirar cotizaciones al cierre del día (proceso automático) | F32: POST | G32: /api/v1/cotizaciones/expiracion | H32: fechaCorte | I32: Cotizaciones evaluadas, vencidas y con pago | J32: HU-019 | K32: Pública (invocada por el programador de tareas) | L32: Especificada en historia de usuario (Corte 2) | M32: Reemplaza PUT /cotizaciones/{id}/estado del Corte 1.
A33: API-03-OP08 | B33: cotizaciones.api | C33: MOD-03 Gestión de Cotizaciones | D33: SUB-06 | E33: Consultar historial de cotizaciones por cliente | F33: GET | G33: /api/v1/clientes/{clienteId}/cotizaciones | H33: clienteId | I33: Cotizaciones del cliente con su estado | J33: HU-020 | K33: Pública | L33: Definida en Corte 1, pendiente de refinamiento
A34: API-03-OP09 | B34: cotizaciones.api | C34: MOD-03 Gestión de Cotizaciones | D34: SUB-06 | E34: Consultar detalle de una cotización | F34: GET | G34: /api/v1/cotizaciones/{cotizacionId} | H34: cotizacionId | I34: Segmentos, precios, vigencia y estado | J34: HU-021 | K34: Interna (consumida por MOD-04) | L34: Definida en Corte 1, pendiente de refinamiento
A35: API-04 · ventas.api · MOD-04 Gestión de Ventas
A36: API-04-OP01 | B36: ventas.api | C36: MOD-04 Gestión de Ventas | D36: SUB-07 | E36: Generar orden de venta desde cotización aceptada | F36: POST | G36: /api/v1/ventas | H36: cotizacionId; condicionesPago (modalidad, fechaLimiteSaldo) | I36: ventaId, segmentos, valorTotal, estado pendiente_pago | J36: HU-021 | K36: Pública | L36: Especificada en historia de usuario (Corte 2)
A37: API-04-OP02 | B37: ventas.api | C37: MOD-04 Gestión de Ventas | D37: SUB-07 | E37: Consultar historial de ventas por cliente | F37: GET | G37: /api/v1/clientes/{clienteId}/ventas | H37: clienteId | I37: Órdenes de venta del cliente | J37: HU-022 | K37: Pública | L37: Definida en Corte 1, pendiente de refinamiento
A38: API-04-OP03 | B38: ventas.api | C38: MOD-04 Gestión de Ventas | D38: SUB-07 | E38: Consultar orden de venta | F38: GET | G38: /api/v1/ventas/{ventaId} | H38: ventaId | I38: Detalle de la orden | J38: HU-028, HU-044 | K38: Pública e interna | L38: Definida en Corte 1, pendiente de refinamiento
A39: API-04-OP04 | B39: ventas.api | C39: MOD-04 Gestión de Ventas | D39: SUB-08 | E39: Registrar cancelación con penalidad o reembolso | F39: POST | G39: /api/v1/ventas/{ventaId}/cancelacion | H39: ventaId; motivo, alcance | I39: Penalidad o reembolso por servicio | J39: HU-023 | K39: Pública | L39: Definida en Corte 1, pendiente de refinamiento
A40: API-04-OP05 | B40: ventas.api | C40: MOD-04 Gestión de Ventas | D40: SUB-08 | E40: Registrar modificación de orden | F40: POST | G40: /api/v1/ventas/{ventaId}/modificacion | H40: ventaId; tipoModificacion, nuevosParametros | I40: Orden modificada | J40: HU-024 | K40: Pública | L40: Definida en Corte 1, pendiente de refinamiento
A41: API-04-OP06 | B41: ventas.api | C41: MOD-04 Gestión de Ventas | D41: SUB-08 | E41: Actualizar estado financiero de la orden | F41: PUT | G41: /api/v1/ventas/{ventaId}/estado-financiero | H41: ventaId; ajustes | I41: Saldo actualizado | J41: HU-023, HU-024 | K41: Pública | L41: Definida en Corte 1, pendiente de refinamiento | M41: FUN-39 es criterio de aceptación de HU-023 y HU-024.
...

Sheet Resumen
A1: Resumen del inventario por API
A2: Conteos calculados con fórmulas sobre la hoja "Inventario APIs".
A4: API | B4: Módulo | C4: Operaciones totales | D4: Especificada en historia de usuario (Corte 2) | E4: Definida en Corte 1, pendiente de refinamiento | F4: Pendiente (Corte 3)
A5: clientes.api | B5: MOD-01 Gestión de Clientes y Solicitudes | C5: =COUNTIF('Inventario APIs'!$B$5:$B$80,A5) -> 10 | D5: =COUNTIFS('Inventario APIs'!$B$5:$B$80,$A5,'Inventario APIs'!$L$5:$L$80,D$4) -> 4 | E5: =COUNTIFS('Inventario APIs'!$B$5:$B$80,$A5,'Inventario APIs'!$L$5:$L$80,E$4) -> 6 | F5: =COUNTIFS('Inventario APIs'!$B$5:$B$80,$A5,'Inventario APIs'!$L$5:$L$80,F$4) -> 0
A6: proveedores.api | B6: MOD-02 Gestión de Proveedores | C6: =COUNTIF('Inventario APIs'!$B$5:$B$80,A6) -> 8 | D6: =COUNTIFS('Inventario APIs'!$B$5:$B$80,$A6,'Inventario APIs'!$L$5:$L$80,D$4) -> 2 | E6: =COUNTIFS('Inventario APIs'!$B$5:$B$80,$A6,'Inventario APIs'!$L$5:$L$80,E$4) -> 2 | F6: =COUNTIFS('Inventario APIs'!$B$5:$B$80,$A6,'Inventario APIs'!$L$5:$L$80,F$4) -> 4
A7: cotizaciones.api | B7: MOD-03 Gestión de Cotizaciones | C7: =COUNTIF('Inventario APIs'!$B$5:$B$80,A7) -> 9 | D7: =COUNTIFS('Inventario APIs'!$B$5:$B$80,$A7,'Inventario APIs'!$L$5:$L$80,D$4) -> 6 | E7: =COUNTIFS('Inventario APIs'!$B$5:$B$80,$A7,'Inventario APIs'!$L$5:$L$80,E$4) -> 2 | F7: =COUNTIFS('Inventario APIs'!$B$5:$B$80,$A7,'Inventario APIs'!$L$5:$L$80,F$4) -> 1
A8: ventas.api | B8: MOD-04 Gestión de Ventas | C8: =COUNTIF('Inventario APIs'!$B$5:$B$80,A8) -> 8 | D8: =COUNTIFS('Inventario APIs'!$B$5:$B$80,$A8,'Inventario APIs'!$L$5:$L$80,D$4) -> 1 | E8: =COUNTIFS('Inventario APIs'!$B$5:$B$80,$A8,'Inventario APIs'!$L$5:$L$80,E$4) -> 7 | F8: =COUNTIFS('Inventario APIs'!$B$5:$B$80,$A8,'Inventario APIs'!$L$5:$L$80,F$4) -> 0
A9: pagos.api | B9: MOD-05 Gestión de Pagos y Tesorería | C9: =COUNTIF('Inventario APIs'!$B$5:$B$80,A9) -> 9 | D9: =COUNTIFS('Inventario APIs'!$B$5:$B$80,$A9,'Inventario APIs'!$L$5:$L$80,D$4) -> 4 | E9: =COUNTIFS('Inventario APIs'!$B$5:$B$80,$A9,'Inventario APIs'!$L$5:$L$80,E$4) -> 2 | F9: =COUNTIFS('Inventario APIs'!$B$5:$B$80,$A9,'Inventario APIs'!$L$5:$L$80,F$4) -> 3
A10: facturacion.api | B10: MOD-06 Gestión de Facturación y Contabilidad | C10: =COUNTIF('Inventario APIs'!$B$5:$B$80,A10) -> 5 | D10: =COUNTIFS('Inventario APIs'!$B$5:$B$80,$A10,'Inventario APIs'!$L$5:$L$80,D$4) -> 1 | E10: =COUNTIFS('Inventario APIs'!$B$5:$B$80,$A10,'Inventario APIs'!$L$5:$L$80,E$4) -> 0 | F10: =COUNTIFS('Inventario APIs'!$B$5:$B$80,$A10,'Inventario APIs'!$L$5:$L$80,F$4) -> 4
A11: reservas.api | B11: MOD-07 Gestión de Reservas y Confirmaciones | C11: =COUNTIF('Inventario APIs'!$B$5:$B$80,A11) -> 11 | D11: =COUNTIFS('Inventario APIs'!$B$5:$B$80,$A11,'Inventario APIs'!$L$5:$L$80,D$4) -> 3 | E11: =COUNTIFS('Inventario APIs'!$B$5:$B$80,$A11,'Inventario APIs'!$L$5:$L$80,E$4) -> 2 | F11: =COUNTIFS('Inventario APIs'!$B$5:$B$80,$A11,'Inventario APIs'!$L$5:$L$80,F$4) -> 6
A12: posventa.api | B12: MOD-08 Seguimiento y Posventa | C12: =COUNTIF('Inventario APIs'!$B$5:$B$80,A12) -> 8 | D12: =COUNTIFS('Inventario APIs'!$B$5:$B$80,$A12,'Inventario APIs'!$L$5:$L$80,D$4) -> 1 | E12: =COUNTIFS('Inventario APIs'!$B$5:$B$80,$A12,'Inventario APIs'!$L$5:$L$80,E$4) -> 1 | F12: =COUNTIFS('Inventario APIs'!$B$5:$B$80,$A12,'Inventario APIs'!$L$5:$L$80,F$4) -> 6
A13: Total | C13: =SUM(C5:C12) -> 68 | D13: =SUM(D5:D12) -> 22 | E13: =SUM(E5:E12) -> 22 | F13: =SUM(F5:F12) -> 24
A15: Historias de usuario cubiertas por el inventario: 52 de 52 (HU-001 a HU-052).

Sheet APIs externas
A1: APIs externas identificadas
A2: Identificadas en el parcial del primer corte. Ninguna está integrada; el negocio hoy no consume ninguna.
A4: ID | B4: API externa | C4: Módulo responsable | D4: Consumidor | E4: Propósito | F4: Historias de usuario relacionadas | G4: Estado | H4: Observaciones
A5: EXT-01 | B5: API Facturación Electrónica DIAN | C5: MOD-06 | D5: Facturación Electrónica y Manual | E5: Transmitir la factura electrónica y obtener el CUFE (RN-51). | F5: HU-032 | G5: Identificada, no integrada
A6: EXT-02 | B6: API de Verificación Migratoria | C6: MOD-07 | D6: Validación de Requisitos Documentales | E6: Verificar automáticamente vigencia de pasaporte y visa (RN-71 a RN-75). | F6: HU-044 | G6: Identificada, no integrada | H6: HU-044 usa un catálogo interno de requisitos mientras no exista la integración.
A7: EXT-03 | B7: API de Tasa de Cambio | C7: MOD-03 | D7: Construcción de Cotización Multiproveedor | E7: Convertir tarifas en dólares antes de aplicar el margen (RN-22). | F7: HU-014 | G7: Identificada, no integrada | H7: Las historias del Corte 2 trabajan en COP.
A8: EXT-04 | B8: API de Mensajería WhatsApp Business | C8: MOD-03 y MOD-08 | D8: Envío de cotizaciones y atención posventa | E8: Automatizar y dejar trazabilidad del canal principal de la agencia. | F8: HU-017, HU-050 | G8: Identificada, no integrada
A9: EXT-05 | B9: API de Clima en Destino | C9: MOD-08 | D9: Seguimiento previo al viaje | E9: Anticipar la viabilidad de actividades compradas en destino. | F9: HU-051 | G9: Identificada, no integrada
A10: EXT-06 | B10: API de Pasarela de Pagos | C10: MOD-05 | D10: Recaudo y Verificación de Pago del Cliente | E10: Verificación automática del ingreso (refuerza RN-42). | F10: HU-025, HU-026 | G10: Identificada, no integrada | H10: Contradicción pendiente: RN-41 solo admite efectivo y transferencia; la pasarela no puede habilitar tarjeta ni financiación.

Sheet Convenciones
A1: Convenciones y leyenda
A2: Reglas aplicadas a todas las operaciones del inventario.
A4: Elemento | B4: Convención
A5: Estructura de respuesta JSON | B5: Toda respuesta contiene success, data y message (exigencia del docente).
A6: Respuesta de error | B6: success = false, data = null y message con texto claro; excepción: 409 por duplicado devuelve el identificador existente.
A7: Versionado de rutas | B7: Prefijo /api/v1, según la plantilla del docente. Las rutas del Corte 1 se muestran con el mismo prefijo.
A8: Nombres de campos | B8: camelCase; fechas YYYY-MM-DD y marcas de tiempo ISO 8601 con -05:00.
A9: Códigos HTTP | B9: 200 consulta o actualización, 201 creación, 400 dato inválido o regla incumplida, 404 recurso inexistente, 409 duplicado, 503 falla de base de datos o plataforma externa.
A10: Eliminación | B10: No se usa DELETE: ningún registro del negocio se elimina, por trazabilidad e historial.
A11: Estado: Especificada en historia de usuario (Corte 2) | B11: La operación está especificada completa con la plantilla del docente en la issue de su historia (columna Gestión Integración del tablero).
A12: Estado: Definida en Corte 1, pendiente de refinamiento | B12: La ruta fue definida en la documentación del Corte 1 o en las comunicaciones internas del parcial; su especificación completa queda para el tercer corte.
A13: Estado: Pendiente (Corte 3) | B13: La operación está identificada por su historia de usuario; método, ruta y datos se definirán al refinar la historia en el tercer corte.
A14: Implementación | B14: Ninguna API está implementada. El inventario refleja diseño y planificación, no código en ejecución.
